<?xml version="1.0"?>

<robot name="al5d">
    <static>false</static>

    <gazebo>
      <plugin name="gazebo_grasp_fix" filename="libgazebo_grasp_fix.so">
        <arm>
           <arm_name>al5d</arm_name>
           <palm_link> hand  </palm_link>
           <gripper_link> gripper_left </gripper_link>
           <gripper_link> gripper_right </gripper_link>
        </arm>
        <forces_angle_tolerance>90</forces_angle_tolerance>
        <update_rate>100</update_rate>
        <grip_count_threshold>1</grip_count_threshold>
        <max_grip_count>2</max_grip_count>
        <release_tolerance>0.005</release_tolerance>
        <disable_collisions_on_attach>false</disable_collisions_on_attach>
        <contact_topic>__default_topic__</contact_topic>
      </plugin>
    </gazebo>

    <!-- Link1 -->
    <gazebo reference="base_link">
        <material>Gazebo/Gold</material>
        <selfCollide>true</selfCollide>
        <gravity>false</gravity>
    </gazebo>

    <!-- Link2 -->
    <gazebo reference="turret">
        <mu1>0.2</mu1>
        <mu2>0.2</mu2>
        <selfCollide>true</selfCollide>
        <material>Gazebo/Black</material>
    </gazebo>

    <!-- Link3 -->
    <gazebo reference="upperarm">
        <mu1>0.2</mu1>
        <mu2>0.2</mu2>
        <selfCollide>true</selfCollide>
        <material>Gazebo/Black</material>
    </gazebo>

    <gazebo reference="forearm">
        <mu1>0.2</mu1>
        <mu2>0.2</mu2>
        <selfCollide>true</selfCollide>
        <material>Gazebo/Gold</material>
    </gazebo>

    <gazebo reference="wrist">
        <mu1>0.2</mu1>
        <mu2>0.2</mu2>
        <selfCollide>true</selfCollide>
        <material>Gazebo/Black</material>
    </gazebo>

    <gazebo reference="hand">
        <mu1>0.2</mu1>
        <mu2>0.2</mu2>
        <selfCollide>true</selfCollide>
        <material>Gazebo/Black</material>
    </gazebo>

    <gazebo reference="gripper_left">
        <mu1>0.2</mu1>
        <mu2>0.2</mu2>
        <selfCollide>true</selfCollide>
        <material>Gazebo/Gold</material>
    </gazebo>

    <gazebo reference="gripper_right">
        <mu1>0.2</mu1>
        <mu2>0.2</mu2>
        <selfCollide>true</selfCollide>
        <material>Gazebo/Gold</material>
    </gazebo>

    <gazebo reference="base_link2turret">
        <fudgeFactor value="0"/>
    </gazebo>

    <gazebo reference="turret2upperarm">
        <fudgeFactor value="0"/>
    </gazebo>

    <gazebo reference="upperarm2forearm">
        <fudgeFactor value="0"/>
    </gazebo>

    <gazebo reference="forearm2wrist">
        <fudgeFactor value="0"/>
    </gazebo>

    <link name="base_link">
        <visual>
            <geometry>
                <cylinder length="0.04" radius="0.095"/>
            </geometry>
            <material name="black">
                <color rgba="0 0 0 1"/>
            </material>
            <origin xyz="0 0 0.02" rpy="0 0 0"/>
        </visual>
        <collision>
            <geometry>
                <cylinder length="0.04" radius="0.095"/>
            </geometry>
            <origin xyz="0 0 0.02" rpy="0 0 0"/>
        </collision>
        <inertial>
            <grafity>0</grafity>
            <origin xyz="0 0 0" rpy="0 0 0"/>
            <mass value="1"/>
            <inertia
                    ixx="1.0" ixy="0.0" ixz="0.0"
                    iyy="1.0" iyz="0.0"
                    izz="1.0"/>
        </inertial>
    </link>

    <link name="turret">
        <visual>
            <geometry>
                <cylinder length="0.005" radius="0.095"/>
            </geometry>
            <material name="black"/>
        </visual>
        <collision>
            <geometry>
                <cylinder length="0.005" radius="0.095"/>
            </geometry>
        </collision>
        <inertial>
            <origin xyz="0 0 0" rpy="0 0 0"/>
            <mass value="1"/>
            <inertia
                    ixx="1.0" ixy="0.0" ixz="0.0"
                    iyy="1.0" iyz="0.0"
                    izz="1.0"/>
        </inertial>
    </link>

    <link name="upperarm">
        <visual>
            <geometry>
                <box size="0.02 0.08 0.18"/>
            </geometry>
            <origin xyz="0 0 0.09" rpy="0 0 0"/>
            <material name="black"/>
        </visual>
        <collision>
            <geometry>
                <box size="0.02 0.08 0.18"/>
            </geometry>
            <origin xyz="0 0 0.09" rpy="0 0 0"/>
        </collision>
        <inertial>
            <origin xyz="0 0 0" rpy="0 0 0"/>
            <mass value="1"/>
            <inertia
                    ixx="1.0" ixy="0.0" ixz="0.0"
                    iyy="1.0" iyz="0.0"
                    izz="1.0"/>
        </inertial>
    </link>

    <link name="forearm">
        <visual>
            <geometry>
                <cylinder length="0.20" radius="0.015"/>
            </geometry>
            <origin xyz="0 0 0.10" rpy="0 0 0"/>
            <material name="silver">
                <color rgba="0.9 0.9 0.9 1"/>
            </material>
        </visual>
        <collision>
            <geometry>
                <cylinder length="0.20" radius="0.015"/>
            </geometry>
            <origin xyz="0 0 0.10" rpy="0 0 0"/>
        </collision>
        <inertial>
            <origin xyz="0 0 0" rpy="0 0 0"/>
            <mass value="1"/>
            <inertia
                    ixx="1.0" ixy="0.0" ixz="0.0"
                    iyy="1.0" iyz="0.0"
                    izz="1.0"/>
        </inertial>
    </link>

    <link name="wrist">
        <visual>
            <geometry>
                <box size="0.02 0.05 0.06"/>
            </geometry>
            <origin xyz="0 0 0.03" rpy="0 0 0"/>
            <material name="black"/>
        </visual>
        <collision>
            <geometry>
                <box size="0.02 0.05 0.06"/>
            </geometry>
            <origin xyz="0 0 0.03" rpy="0 0 0"/>
        </collision>
        <inertial>
            <origin xyz="0 0 0" rpy="0 0 0"/>
            <mass value="1"/>
            <inertia
                    ixx="1.0" ixy="0.0" ixz="0.0"
                    iyy="1.0" iyz="0.0"
                    izz="1.0"/>
        </inertial>
    </link>

    <link name="hand">
        <visual>
            <geometry>
                <box size="0.02 0.07 0.025"/>
            </geometry>
            <origin xyz="0 0 0.0125" rpy="0 0 0"/>
            <material name="black"/>
        </visual>
        <collision>
            <geometry>
                <box size="0.02 0.07 0.025"/>
            </geometry>
            <origin xyz="0 0 0.0125" rpy="0 0 0"/>
        </collision>
        <inertial>
            <origin xyz="0 0 0" rpy="0 0 0"/>
            <mass value="1"/>
            <inertia
                    ixx="1.0" ixy="0.0" ixz="0.0"
                    iyy="1.0" iyz="0.0"
                    izz="1.0"/>
        </inertial>
    </link>

    <link name="gripper_left">
        <visual>
            <geometry>
                <box size="0.02 0.02 0.03"/>
            </geometry>
            <origin xyz="0 0 0" rpy="0 0 0"/>
            <material name="gray">
                <color rgba="0.3 0.3 0.3 1"/>
            </material>
        </visual>
        <collision>
            <geometry>
                <box size="0.02 0.02 0.03"/>
            </geometry>
            <origin xyz="0 0 0" rpy="0 0 0"/>
        </collision>
        <inertial>
            <origin xyz="0 0 0" rpy="0 0 0"/>
            <mass value="1"/>
            <inertia
                    ixx="1.0" ixy="0.0" ixz="0.0"
                    iyy="1.0" iyz="0.0"
                    izz="1.0"/>
        </inertial>
    </link>

    <link name="gripper_right">
        <visual>
            <geometry>
                <box size="0.02 0.02 0.03"/>
            </geometry>
            <origin xyz="0 0 0" rpy="0 0 0"/>
            <material name="gray"/>
        </visual>
        <collision>
            <geometry>
                <box size="0.02 0.02 0.03"/>
            </geometry>
            <origin xyz="0 0 0" rpy="0 0 0"/>
        </collision>
        <inertial>
            <origin xyz="0 0 0" rpy="0 0 0"/>
            <mass value="1"/>
            <inertia
                    ixx="1.0" ixy="0.0" ixz="0.0"
                    iyy="1.0" iyz="0.0"
                    izz="1.0"/>
        </inertial>
    </link>

    <joint name="base_link2turret" type="continuous">
        <parent link="base_link"/>
        <child link="turret"/>
        <origin xyz="0 0 0.045" rpy="0 0 0"/>
        <axis xyz="0 0 -1"/>
    </joint>
    <joint name="turret2upperarm" type="continuous">
        <parent link="turret"/>
        <child link="upperarm"/>
        <origin xyz="0 0 0.02" rpy="0 0 0"/>
        <axis xyz="0 1 0"/>
    </joint>
    <joint name="upperarm2forearm" type="continuous">
        <parent link="upperarm"/>
        <child link="forearm"/>
        <origin xyz="0 0 0.18" rpy="0 0 0"/>
        <axis xyz="0 1 0"/>
    </joint>
    <joint name="forearm2wrist" type="continuous">
        <parent link="forearm"/>
        <child link="wrist"/>
        <origin xyz="0 0 0.20" rpy="0 0 0"/>
        <axis xyz="0 -1 0"/>
    </joint>
    <joint name="wrist2hand" type="continuous">
        <parent link="wrist"/>
        <child link="hand"/>
        <origin xyz="0 0 0.06" rpy="0 0 0"/>
        <axis xyz="0 0 -1"/>
    </joint>
    <joint name="gripper_left2hand" type="prismatic">
        <parent link="hand"/>
        <child link="gripper_left"/>
        <origin xyz="0 0.025 0.04" rpy="0 0 0"/>
        <limit effort="1000.0" lower="-0.02" upper="0.02" velocity="0.5"/>
        <axis xyz="0 -1 0"/>
    </joint>
    <joint name="gripper_right2hand" type="prismatic">
        <parent link="hand"/>
        <child link="gripper_right"/>
        <origin xyz="0 -0.025 0.04" rpy="0 0 0"/>
        <limit effort="1000.0" lower="-0.02" upper="0.02" velocity="0.5"/>
        <axis xyz="0 1 0"/>
        <mimic joint="gripper_left2hand" multiplier="1" offset="0"/>
    </joint>
    <link name="world"/>
    <joint name="fixed" type="fixed">
        <parent link="world"/>
        <child link="base_link"/>
    </joint>

    <gazebo>
        <plugin name="robot_simulation" filename="libsim_robot_plugin.so">
            <joint_info name="base_link2turret" channel="0">
                <min_pw>800</min_pw>
                <max_pw>2400</max_pw>
                <min_rad>-1.57</min_rad>
                <max_rad>1.57</max_rad>
                <max_vel>2</max_vel>
            </joint_info>
            <joint_info name="turret2upperarm" channel="1">
                <min_pw>725</min_pw>
                <max_pw>1850</max_pw>
                <min_rad>1.57</min_rad>
                <max_rad>-0.52</max_rad>
                <max_vel>2</max_vel>
            </joint_info>
            <joint_info name="upperarm2forearm" channel="2">
                <min_pw>700</min_pw>
                <max_pw>1900</max_pw>
                <min_rad>0</min_rad>
                <max_rad>2.36</max_rad>
                <max_vel>2</max_vel>
            </joint_info>
            <joint_info name="forearm2wrist" channel="3">
                <min_pw>610</min_pw>
                <max_pw>2480</max_pw>
                <min_rad>-1.57</min_rad>
                <max_rad>1.57</max_rad>
                <max_vel>2</max_vel>
            </joint_info>
            <joint_info name="wrist2hand" channel="5">
                <min_pw>500</min_pw>
                <max_pw>2400</max_pw>
                <min_rad>-1.57</min_rad>
                <max_rad>1.57</max_rad>
                <max_vel>2</max_vel>
            </joint_info>
            <joint_info name="gripper_left2hand" channel="4">
                <min_pw>500</min_pw>
                <max_pw>2500</max_pw>
        	<min_rad>-0.01975</min_rad>
        	<max_rad>0.01975</max_rad>
        	<max_vel>2.870</max_vel>
            </joint_info>
        </plugin>
    </gazebo>
   
   <gazebo>
     <plugin name="mimic_joint_plugin_gripper" filename="libroboticsgroup_gazebo_mimic_joint_plugin.so">
       <joint>gripper_left2hand</joint>
       <mimicJoint>gripper_right2hand</mimicJoint>
     </plugin>
  </gazebo>

</robot>
